[2021-04-10 01:22:12,779][INFO]: initializing app...
[2021-04-10 01:22:12,793][INFO]: detecting remote's version...
[2021-04-10 01:22:12,797][INFO]: detected remote's version: 1.9.8
[2021-04-10 01:22:12,802][INFO]: using pure websocket to receive event
[2021-04-10 01:22:12,804][INFO]: event receive method checked.
[2021-04-10 01:22:12,806][INFO]: this application's initialization has been completed.
[2021-04-10 01:22:12,806][INFO]: --- setting start ---
[2021-04-10 01:22:12,806][INFO]: broadcast using: <graia.broadcast.Broadcast object at 0x7fcd0595f580>
[2021-04-10 01:22:12,806][INFO]: enable log of chat: yes
[2021-04-10 01:22:12,806][INFO]: debug: no
[2021-04-10 01:22:12,806][INFO]: version(remote): 1.9.8
[2021-04-10 01:22:12,806][INFO]: --- setting end ---
[2021-04-10 01:22:12,806][INFO]: application has been initialized, used 0.0272s
[2021-04-10 01:22:12,806][INFO]: websocket daemon: websocket connection starting...
[2021-04-10 01:22:12,813][INFO]: websocket: connected
[2021-04-10 01:22:12,813][INFO]: websocket: ping task created
[2021-04-10 01:22:21,476][INFO]: 246987206: [bot(1020661362] 矛盾体🙃(1337795211) -> '[mirai:source:4273,1617988941]翻译'
[2021-04-10 01:22:21,753][INFO]: [BOT 246987206] Group(1020661362) <- '[mirai:at:1337795211,None]好的'
Traceback (most recent call last):
  File "/root/mirai/code/fanyi.py", line 97, in fanyi
    img_url = content.messageChain.get(Image)[0].url
IndexError: list index out of range

During handling of the above exception, another exception occurred:

Traceback (most recent call last):
  File "/usr/local/lib/python3.8/dist-packages/graia/broadcast/__init__.py", line 204, in Executor
    result = await run_always_await_safely(
  File "/usr/local/lib/python3.8/dist-packages/graia/broadcast/utilles.py", line 30, in run_always_await_safely
    return await callable(*args, **kwargs)
  File "/root/mirai/code/fanyi.py", line 110, in fanyi
    At(content.send.id),Plain("好的")
AttributeError: 'GroupMessage' object has no attribute 'send'
[2021-04-10 01:22:22,715][INFO]: 246987206: [bot(1020661362] 矛盾体🙃(1337795211) -> '[mirai:source:4275,1617988942]翻译'
[2021-04-10 01:22:22,994][INFO]: [BOT 246987206] Group(1020661362) <- '[mirai:at:1337795211,None]好的'
Traceback (most recent call last):
  File "/root/mirai/code/fanyi.py", line 97, in fanyi
    img_url = content.messageChain.get(Image)[0].url
IndexError: list index out of range

During handling of the above exception, another exception occurred:

Traceback (most recent call last):
  File "/usr/local/lib/python3.8/dist-packages/graia/broadcast/__init__.py", line 204, in Executor
    result = await run_always_await_safely(
  File "/usr/local/lib/python3.8/dist-packages/graia/broadcast/utilles.py", line 30, in run_always_await_safely
    return await callable(*args, **kwargs)
  File "/root/mirai/code/fanyi.py", line 110, in fanyi
    At(content.send.id),Plain("好的")
AttributeError: 'GroupMessage' object has no attribute 'send'
[2021-04-10 01:22:24,015][INFO]: 246987206: [bot(1020661362] 矛盾体🙃(1337795211) -> '[mirai:source:4277,1617988943]翻译'
[2021-04-10 01:22:24,273][INFO]: [BOT 246987206] Group(1020661362) <- '[mirai:at:1337795211,None]好的'
Traceback (most recent call last):
  File "/root/mirai/code/fanyi.py", line 97, in fanyi
    img_url = content.messageChain.get(Image)[0].url
IndexError: list index out of range

During handling of the above exception, another exception occurred:

Traceback (most recent call last):
  File "/usr/local/lib/python3.8/dist-packages/graia/broadcast/__init__.py", line 204, in Executor
    result = await run_always_await_safely(
  File "/usr/local/lib/python3.8/dist-packages/graia/broadcast/utilles.py", line 30, in run_always_await_safely
    return await callable(*args, **kwargs)
  File "/root/mirai/code/fanyi.py", line 110, in fanyi
    At(content.send.id),Plain("好的")
AttributeError: 'GroupMessage' object has no attribute 'send'
[2021-04-10 01:22:25,333][INFO]: 246987206: [bot(1020661362] 矛盾体🙃(1337795211) -> '[mirai:source:4279,1617988945]翻译'
[2021-04-10 01:22:25,629][INFO]: [BOT 246987206] Group(1020661362) <- '[mirai:at:1337795211,None]好的'
Traceback (most recent call last):
  File "/root/mirai/code/fanyi.py", line 97, in fanyi
    img_url = content.messageChain.get(Image)[0].url
IndexError: list index out of range

During handling of the above exception, another exception occurred:

Traceback (most recent call last):
  File "/usr/local/lib/python3.8/dist-packages/graia/broadcast/__init__.py", line 204, in Executor
    result = await run_always_await_safely(
  File "/usr/local/lib/python3.8/dist-packages/graia/broadcast/utilles.py", line 30, in run_always_await_safely
    return await callable(*args, **kwargs)
  File "/root/mirai/code/fanyi.py", line 110, in fanyi
    At(content.send.id),Plain("好的")
AttributeError: 'GroupMessage' object has no attribute 'send'
[2021-04-10 01:22:27,066][INFO]: 246987206: [bot(1020661362] 矛盾体🙃(1337795211) -> '[mirai:source:4281,1617988946]翻译'
[2021-04-10 01:22:27,341][INFO]: [BOT 246987206] Group(1020661362) <- '[mirai:at:1337795211,None]好的'
Traceback (most recent call last):
  File "/root/mirai/code/fanyi.py", line 97, in fanyi
    img_url = content.messageChain.get(Image)[0].url
IndexError: list index out of range

During handling of the above exception, another exception occurred:

Traceback (most recent call last):
  File "/usr/local/lib/python3.8/dist-packages/graia/broadcast/__init__.py", line 204, in Executor
    result = await run_always_await_safely(
  File "/usr/local/lib/python3.8/dist-packages/graia/broadcast/utilles.py", line 30, in run_always_await_safely
    return await callable(*args, **kwargs)
  File "/root/mirai/code/fanyi.py", line 110, in fanyi
    At(content.send.id),Plain("好的")
AttributeError: 'GroupMessage' object has no attribute 'send'
[2021-04-10 01:22:28,266][INFO]: 246987206: [bot(1020661362] 矛盾体🙃(1337795211) -> '[mirai:source:4283,1617988948]翻译'
[2021-04-10 01:22:28,521][INFO]: [BOT 246987206] Group(1020661362) <- '[mirai:at:1337795211,None]好的'
Traceback (most recent call last):
  File "/root/mirai/code/fanyi.py", line 97, in fanyi
    img_url = content.messageChain.get(Image)[0].url
IndexError: list index out of range

During handling of the above exception, another exception occurred:

Traceback (most recent call last):
  File "/usr/local/lib/python3.8/dist-packages/graia/broadcast/__init__.py", line 204, in Executor
    result = await run_always_await_safely(
  File "/usr/local/lib/python3.8/dist-packages/graia/broadcast/utilles.py", line 30, in run_always_await_safely
    return await callable(*args, **kwargs)
  File "/root/mirai/code/fanyi.py", line 110, in fanyi
    At(content.send.id),Plain("好的")
AttributeError: 'GroupMessage' object has no attribute 'send'
[2021-04-10 01:22:29,410][INFO]: 246987206: [bot(1020661362] 矛盾体🙃(1337795211) -> '[mirai:source:4285,1617988949]翻译'
[2021-04-10 01:22:29,707][INFO]: [BOT 246987206] Group(1020661362) <- '[mirai:at:1337795211,None]好的'
Traceback (most recent call last):
  File "/root/mirai/code/fanyi.py", line 97, in fanyi
    img_url = content.messageChain.get(Image)[0].url
IndexError: list index out of range

During handling of the above exception, another exception occurred:

Traceback (most recent call last):
  File "/usr/local/lib/python3.8/dist-packages/graia/broadcast/__init__.py", line 204, in Executor
    result = await run_always_await_safely(
  File "/usr/local/lib/python3.8/dist-packages/graia/broadcast/utilles.py", line 30, in run_always_await_safely
    return await callable(*args, **kwargs)
  File "/root/mirai/code/fanyi.py", line 110, in fanyi
    At(content.send.id),Plain("好的")
AttributeError: 'GroupMessage' object has no attribute 'send'
[2021-04-10 01:22:30,649][INFO]: 246987206: [bot(1020661362] 矛盾体🙃(1337795211) -> '[mirai:source:4287,1617988950]翻译'
[2021-04-10 01:22:30,934][INFO]: [BOT 246987206] Group(1020661362) <- '[mirai:at:1337795211,None]好的'
Traceback (most recent call last):
  File "/root/mirai/code/fanyi.py", line 97, in fanyi
    img_url = content.messageChain.get(Image)[0].url
IndexError: list index out of range

During handling of the above exception, another exception occurred:

Traceback (most recent call last):
  File "/usr/local/lib/python3.8/dist-packages/graia/broadcast/__init__.py", line 204, in Executor
    result = await run_always_await_safely(
  File "/usr/local/lib/python3.8/dist-packages/graia/broadcast/utilles.py", line 30, in run_always_await_safely
    return await callable(*args, **kwargs)
  File "/root/mirai/code/fanyi.py", line 110, in fanyi
    At(content.send.id),Plain("好的")
AttributeError: 'GroupMessage' object has no attribute 'send'
[2021-04-10 01:22:31,718][INFO]: 246987206: [bot(1020661362] 矛盾体🙃(1337795211) -> '[mirai:source:4289,1617988951]翻译'
[2021-04-10 01:22:31,979][INFO]: [BOT 246987206] Group(1020661362) <- '[mirai:at:1337795211,None]好的'
Traceback (most recent call last):
  File "/root/mirai/code/fanyi.py", line 97, in fanyi
    img_url = content.messageChain.get(Image)[0].url
IndexError: list index out of range

During handling of the above exception, another exception occurred:

Traceback (most recent call last):
  File "/usr/local/lib/python3.8/dist-packages/graia/broadcast/__init__.py", line 204, in Executor
    result = await run_always_await_safely(
  File "/usr/local/lib/python3.8/dist-packages/graia/broadcast/utilles.py", line 30, in run_always_await_safely
    return await callable(*args, **kwargs)
  File "/root/mirai/code/fanyi.py", line 110, in fanyi
    At(content.send.id),Plain("好的")
AttributeError: 'GroupMessage' object has no attribute 'send'
[2021-04-10 01:22:32,998][INFO]: 246987206: [bot(1020661362] 矛盾体🙃(1337795211) -> '[mirai:source:4291,1617988952]翻译'
[2021-04-10 01:22:33,305][INFO]: [BOT 246987206] Group(1020661362) <- '[mirai:at:1337795211,None]好的'
[2021-04-10 01:22:40,841][INFO]: 246987206: [bot(1020661362] 矛盾体🙃(1337795211) -> '[mirai:source:4293,1617988960]kuso'
[2021-04-10 01:22:41,309][INFO]: [BOT 246987206] Group(1020661362) <- '[mirai:at:1337795211,None]kuso:至'
[2021-04-10 01:22:44,526][INFO]: 246987206: [bot(1020661362] 矛盾体🙃(1337795211) -> '[mirai:source:4295,1617988964]？'
[2021-04-10 01:22:45,265][INFO]: [BOT 246987206] Group(1020661362) <- '[mirai:at:1337795211,None]？:？'
[2021-04-10 01:22:50,089][INFO]: 246987206: [bot(1020661362] ajt（｀Δ´）！(342472121) -> '[mirai:source:4297,1617988969]欸我的禁言机制呢'
Traceback (most recent call last):
  File "/root/mirai/code/fanyi.py", line 97, in fanyi
    img_url = content.messageChain.get(Image)[0].url
IndexError: list index out of range

During handling of the above exception, another exception occurred:

Traceback (most recent call last):
  File "/usr/local/lib/python3.8/dist-packages/graia/broadcast/__init__.py", line 204, in Executor
    result = await run_always_await_safely(
  File "/usr/local/lib/python3.8/dist-packages/graia/broadcast/utilles.py", line 30, in run_always_await_safely
    return await callable(*args, **kwargs)
  File "/root/mirai/code/fanyi.py", line 110, in fanyi
    At(content.send.id),Plain("好的")
AttributeError: 'GroupMessage' object has no attribute 'send'
[2021-04-10 01:22:54,574][INFO]: 246987206: [bot(1020661362] 矛盾体🙃(1337795211) -> '[mirai:source:4298,1617988974]翻译'
[2021-04-10 01:22:54,813][INFO]: [BOT 246987206] Group(1020661362) <- '[mirai:at:1337795211,None]好的'
Traceback (most recent call last):
  File "/root/mirai/code/fanyi.py", line 97, in fanyi
    img_url = content.messageChain.get(Image)[0].url
IndexError: list index out of range

During handling of the above exception, another exception occurred:

Traceback (most recent call last):
  File "/usr/local/lib/python3.8/dist-packages/graia/broadcast/__init__.py", line 204, in Executor
    result = await run_always_await_safely(
  File "/usr/local/lib/python3.8/dist-packages/graia/broadcast/utilles.py", line 30, in run_always_await_safely
    return await callable(*args, **kwargs)
  File "/root/mirai/code/fanyi.py", line 110, in fanyi
    At(content.send.id),Plain("好的")
AttributeError: 'GroupMessage' object has no attribute 'send'
[2021-04-10 01:22:57,261][INFO]: 246987206: [bot(1020661362] 矛盾体🙃(1337795211) -> '[mirai:source:4300,1617988977]翻译'
[2021-04-10 01:22:57,529][INFO]: [BOT 246987206] Group(1020661362) <- '[mirai:at:1337795211,None]好的'
Traceback (most recent call last):
  File "/root/mirai/code/fanyi.py", line 97, in fanyi
    img_url = content.messageChain.get(Image)[0].url
IndexError: list index out of range

During handling of the above exception, another exception occurred:

Traceback (most recent call last):
  File "/usr/local/lib/python3.8/dist-packages/graia/broadcast/__init__.py", line 204, in Executor
    result = await run_always_await_safely(
  File "/usr/local/lib/python3.8/dist-packages/graia/broadcast/utilles.py", line 30, in run_always_await_safely
    return await callable(*args, **kwargs)
  File "/root/mirai/code/fanyi.py", line 110, in fanyi
    At(content.send.id),Plain("好的")
AttributeError: 'GroupMessage' object has no attribute 'send'
[2021-04-10 01:22:58,376][INFO]: 246987206: [bot(1020661362] 矛盾体🙃(1337795211) -> '[mirai:source:4302,1617988978]翻译'
[2021-04-10 01:22:58,681][INFO]: [BOT 246987206] Group(1020661362) <- '[mirai:at:1337795211,None]好的'
Traceback (most recent call last):
  File "/root/mirai/code/fanyi.py", line 97, in fanyi
    img_url = content.messageChain.get(Image)[0].url
IndexError: list index out of range

During handling of the above exception, another exception occurred:

Traceback (most recent call last):
  File "/usr/local/lib/python3.8/dist-packages/graia/broadcast/__init__.py", line 204, in Executor
    result = await run_always_await_safely(
  File "/usr/local/lib/python3.8/dist-packages/graia/broadcast/utilles.py", line 30, in run_always_await_safely
    return await callable(*args, **kwargs)
  File "/root/mirai/code/fanyi.py", line 110, in fanyi
    At(content.send.id),Plain("好的")
AttributeError: 'GroupMessage' object has no attribute 'send'
[2021-04-10 01:22:59,657][INFO]: 246987206: [bot(1020661362] 矛盾体🙃(1337795211) -> '[mirai:source:4304,1617988979]翻译'
[2021-04-10 01:22:59,894][INFO]: [BOT 246987206] Group(1020661362) <- '[mirai:at:1337795211,None]好的'
[2021-04-10 01:23:00,926][INFO]: 246987206: [bot(1020661362] 矛盾体🙃(1337795211) -> '[mirai:source:4306,1617988980]help'
[2021-04-10 01:23:01,181][INFO]: [BOT 246987206] Group(1020661362) <- '[mirai:at:1337795211,None]\n[mirai:face:298]成语接龙\n[mirai:face:298]选择\n[mirai:face:298]compile\n[mirai:face:298]guess\n[mirai:face:298]智能聊天\n[mirai:face:298]daily english\n[mirai:face:298]青年大学习\n[mirai:face:298]毒鸡汤\n[mirai:face:298]leetcode\n[mirai:face:298]色图\n[mirai:face:298]天气\n[mirai:face:298]翻译\n[mirai:face:298]具体请help 功能'
[2021-04-10 01:23:11,379][INFO]: 246987206: [bot(1020661362] 矛盾体🙃(1337795211) -> '[mirai:source:4308,1617988991]翻译'
[2021-04-10 01:23:11,669][INFO]: [BOT 246987206] Group(1020661362) <- '[mirai:at:1337795211,None]好的'
Traceback (most recent call last):
  File "/root/mirai/code/fanyi.py", line 97, in fanyi
    img_url = content.messageChain.get(Image)[0].url
IndexError: list index out of range

During handling of the above exception, another exception occurred:

Traceback (most recent call last):
  File "/usr/local/lib/python3.8/dist-packages/graia/broadcast/__init__.py", line 204, in Executor
    result = await run_always_await_safely(
  File "/usr/local/lib/python3.8/dist-packages/graia/broadcast/utilles.py", line 30, in run_always_await_safely
    return await callable(*args, **kwargs)
  File "/root/mirai/code/fanyi.py", line 110, in fanyi
    At(content.send.id),Plain("好的")
AttributeError: 'GroupMessage' object has no attribute 'send'
[2021-04-10 01:23:12,297][INFO]: 246987206: [bot(1020661362] 矛盾体🙃(1337795211) -> '[mirai:source:4310,1617988992]翻译'
[2021-04-10 01:23:12,534][INFO]: [BOT 246987206] Group(1020661362) <- '[mirai:at:1337795211,None]好的'
Traceback (most recent call last):
  File "/root/mirai/code/fanyi.py", line 97, in fanyi
    img_url = content.messageChain.get(Image)[0].url
IndexError: list index out of range

During handling of the above exception, another exception occurred:

Traceback (most recent call last):
  File "/usr/local/lib/python3.8/dist-packages/graia/broadcast/__init__.py", line 204, in Executor
    result = await run_always_await_safely(
  File "/usr/local/lib/python3.8/dist-packages/graia/broadcast/utilles.py", line 30, in run_always_await_safely
    return await callable(*args, **kwargs)
  File "/root/mirai/code/fanyi.py", line 110, in fanyi
    At(content.send.id),Plain("好的")
AttributeError: 'GroupMessage' object has no attribute 'send'
[2021-04-10 01:23:13,291][INFO]: 246987206: [bot(1020661362] 矛盾体🙃(1337795211) -> '[mirai:source:4312,1617988993]翻译'
[2021-04-10 01:23:13,554][INFO]: [BOT 246987206] Group(1020661362) <- '[mirai:at:1337795211,None]好的'
Traceback (most recent call last):
  File "/root/mirai/code/fanyi.py", line 97, in fanyi
    img_url = content.messageChain.get(Image)[0].url
IndexError: list index out of range

During handling of the above exception, another exception occurred:

Traceback (most recent call last):
  File "/usr/local/lib/python3.8/dist-packages/graia/broadcast/__init__.py", line 204, in Executor
    result = await run_always_await_safely(
  File "/usr/local/lib/python3.8/dist-packages/graia/broadcast/utilles.py", line 30, in run_always_await_safely
    return await callable(*args, **kwargs)
  File "/root/mirai/code/fanyi.py", line 110, in fanyi
    At(content.send.id),Plain("好的")
AttributeError: 'GroupMessage' object has no attribute 'send'
[2021-04-10 01:23:14,409][INFO]: 246987206: [bot(1020661362] 矛盾体🙃(1337795211) -> '[mirai:source:4314,1617988994]翻译'
[2021-04-10 01:23:14,718][INFO]: [BOT 246987206] Group(1020661362) <- '[mirai:at:1337795211,None]好的'
Traceback (most recent call last):
  File "/root/mirai/code/fanyi.py", line 97, in fanyi
    img_url = content.messageChain.get(Image)[0].url
IndexError: list index out of range

During handling of the above exception, another exception occurred:

Traceback (most recent call last):
  File "/usr/local/lib/python3.8/dist-packages/graia/broadcast/__init__.py", line 204, in Executor
    result = await run_always_await_safely(
  File "/usr/local/lib/python3.8/dist-packages/graia/broadcast/utilles.py", line 30, in run_always_await_safely
    return await callable(*args, **kwargs)
  File "/root/mirai/code/fanyi.py", line 110, in fanyi
    At(content.send.id),Plain("好的")
AttributeError: 'GroupMessage' object has no attribute 'send'
[2021-04-10 01:23:15,390][INFO]: 246987206: [bot(1020661362] 矛盾体🙃(1337795211) -> '[mirai:source:4316,1617988995]翻译'
[2021-04-10 01:23:15,659][INFO]: [BOT 246987206] Group(1020661362) <- '[mirai:at:1337795211,None]好的'
Traceback (most recent call last):
  File "/root/mirai/code/fanyi.py", line 97, in fanyi
    img_url = content.messageChain.get(Image)[0].url
IndexError: list index out of range

During handling of the above exception, another exception occurred:

Traceback (most recent call last):
  File "/usr/local/lib/python3.8/dist-packages/graia/broadcast/__init__.py", line 204, in Executor
    result = await run_always_await_safely(
  File "/usr/local/lib/python3.8/dist-packages/graia/broadcast/utilles.py", line 30, in run_always_await_safely
    return await callable(*args, **kwargs)
  File "/root/mirai/code/fanyi.py", line 110, in fanyi
    At(content.send.id),Plain("好的")
AttributeError: 'GroupMessage' object has no attribute 'send'
[2021-04-10 01:23:16,439][INFO]: 246987206: [bot(1020661362] 矛盾体🙃(1337795211) -> '[mirai:source:4318,1617988996]翻译'
[2021-04-10 01:23:16,690][INFO]: [BOT 246987206] Group(1020661362) <- '[mirai:at:1337795211,None]好的'
[2021-04-10 01:23:46,376][INFO]: 246987206: [bot(1020661362] 矛盾体🙃(1337795211) -> '[mirai:source:4320,1617989026]检查一下您的逻辑错误[mirai:face:298]'
[2021-04-10 01:23:47,150][INFO]: [BOT 246987206] Group(1020661362) <- '[mirai:at:1337795211,None]检查一下您的逻辑错误[_表情]:检查一下您的逻辑错误[_表情]'
[2021-04-10 01:24:16,880][INFO]: 246987206: [bot(1020661362] ajt（｀Δ´）！(342472121) -> '[mirai:source:4322,1617989056][mirai:image:{EE472993-F4DC-D734-B766-5605F537FFE1}.jpg]检查出来没'
