[2021-04-10 16:28:47,349][INFO]: initializing app...

-------------------------------------------------------------------------------
main.py 19 <module>
app.launch_blocking()

__init__.py 1574 launch_blocking
loop.run_until_complete(self.initialize())

base_events.py 616 run_until_complete
return future.result()

__init__.py 1464 initialize
await self.authenticate()

utilles.py 27 wrapper
return await func(self, *args, **kwargs)

__init__.py 301 authenticate
async with self.session.post(

client.py 1117 __aenter__
self._resp = await self._coro

client.py 520 _request
conn = await self._connector.connect(

connector.py 535 connect
proto = await self._create_connection(req, traces, timeout)

connector.py 892 _create_connection
_, proto = await self._create_direct_connection(req, traces, timeout)

connector.py 1051 _create_direct_connection
raise last_exc

connector.py 1020 _create_direct_connection
transp, proto = await self._wrap_create_connection(

connector.py 975 _wrap_create_connection
raise client_error(req.connection_key, exc) from exc

aiohttp.client_exceptions.ClientConnectorError:
ConnectionKey(host='localhost', port=8080, is_ssl=False, ssl=None, proxy=None, proxy_auth=None, proxy_headers_hash=None)
[Errno 111] Connect call failed ('127.0.0.1', 8080)
